2020-07-03 11:20:42,250 ERROR: Exception on / [GET] [in /Users/justinlabrash/Documents/flask_project/venv/lib/python3.8/site-packages/flask/app.py:1891]
Traceback (most recent call last):
  File "/Users/justinlabrash/Documents/flask_project/venv/lib/python3.8/site-packages/flask/app.py", line 2447, in wsgi_app
    response = self.full_dispatch_request()
  File "/Users/justinlabrash/Documents/flask_project/venv/lib/python3.8/site-packages/flask/app.py", line 1952, in full_dispatch_request
    rv = self.handle_user_exception(e)
  File "/Users/justinlabrash/Documents/flask_project/venv/lib/python3.8/site-packages/flask/app.py", line 1821, in handle_user_exception
    reraise(exc_type, exc_value, tb)
  File "/Users/justinlabrash/Documents/flask_project/venv/lib/python3.8/site-packages/flask/_compat.py", line 39, in reraise
    raise value
  File "/Users/justinlabrash/Documents/flask_project/venv/lib/python3.8/site-packages/flask/app.py", line 1948, in full_dispatch_request
    rv = self.preprocess_request()
  File "/Users/justinlabrash/Documents/flask_project/venv/lib/python3.8/site-packages/flask/app.py", line 2242, in preprocess_request
    rv = func()
  File "/Users/justinlabrash/Documents/flask_project/flask_app/main/routes.py", line 18, in before_request
    g.locale = str(get_locale())
NameError: name 'get_locale' is not defined
2020-07-03 11:22:01,604 INFO: Microblog startup [in /Users/justinlabrash/Documents/flask_project/flask_app/__init__.py:75]
2020-07-03 11:22:02,883 ERROR: Exception on / [GET] [in /Users/justinlabrash/Documents/flask_project/venv/lib/python3.8/site-packages/flask/app.py:1891]
Traceback (most recent call last):
  File "/Users/justinlabrash/Documents/flask_project/venv/lib/python3.8/site-packages/flask/app.py", line 2447, in wsgi_app
    response = self.full_dispatch_request()
  File "/Users/justinlabrash/Documents/flask_project/venv/lib/python3.8/site-packages/flask/app.py", line 1952, in full_dispatch_request
    rv = self.handle_user_exception(e)
  File "/Users/justinlabrash/Documents/flask_project/venv/lib/python3.8/site-packages/flask/app.py", line 1821, in handle_user_exception
    reraise(exc_type, exc_value, tb)
  File "/Users/justinlabrash/Documents/flask_project/venv/lib/python3.8/site-packages/flask/_compat.py", line 39, in reraise
    raise value
  File "/Users/justinlabrash/Documents/flask_project/venv/lib/python3.8/site-packages/flask/app.py", line 1948, in full_dispatch_request
    rv = self.preprocess_request()
  File "/Users/justinlabrash/Documents/flask_project/venv/lib/python3.8/site-packages/flask/app.py", line 2242, in preprocess_request
    rv = func()
  File "/Users/justinlabrash/Documents/flask_project/flask_app/main/routes.py", line 18, in before_request
    g.locale = str(get_locale())
NameError: name 'get_locale' is not defined
2020-07-03 11:23:10,190 INFO: Microblog startup [in /Users/justinlabrash/Documents/flask_project/flask_app/__init__.py:75]
2020-07-03 11:23:11,269 ERROR: Exception on / [GET] [in /Users/justinlabrash/Documents/flask_project/venv/lib/python3.8/site-packages/flask/app.py:1891]
Traceback (most recent call last):
  File "/Users/justinlabrash/Documents/flask_project/venv/lib/python3.8/site-packages/flask/app.py", line 2447, in wsgi_app
    response = self.full_dispatch_request()
  File "/Users/justinlabrash/Documents/flask_project/venv/lib/python3.8/site-packages/flask/app.py", line 1952, in full_dispatch_request
    rv = self.handle_user_exception(e)
  File "/Users/justinlabrash/Documents/flask_project/venv/lib/python3.8/site-packages/flask/app.py", line 1821, in handle_user_exception
    reraise(exc_type, exc_value, tb)
  File "/Users/justinlabrash/Documents/flask_project/venv/lib/python3.8/site-packages/flask/_compat.py", line 39, in reraise
    raise value
  File "/Users/justinlabrash/Documents/flask_project/venv/lib/python3.8/site-packages/flask/app.py", line 1948, in full_dispatch_request
    rv = self.preprocess_request()
  File "/Users/justinlabrash/Documents/flask_project/venv/lib/python3.8/site-packages/flask/app.py", line 2242, in preprocess_request
    rv = func()
  File "/Users/justinlabrash/Documents/flask_project/flask_app/main/routes.py", line 18, in before_request
    g.locale = str(get_locale())
NameError: name 'get_locale' is not defined
2020-07-03 11:23:34,254 INFO: Microblog startup [in /Users/justinlabrash/Documents/flask_project/flask_app/__init__.py:75]
2020-07-03 11:23:35,240 ERROR: Exception on / [GET] [in /Users/justinlabrash/Documents/flask_project/venv/lib/python3.8/site-packages/flask/app.py:1891]
Traceback (most recent call last):
  File "/Users/justinlabrash/Documents/flask_project/venv/lib/python3.8/site-packages/flask/app.py", line 2447, in wsgi_app
    response = self.full_dispatch_request()
  File "/Users/justinlabrash/Documents/flask_project/venv/lib/python3.8/site-packages/flask/app.py", line 1952, in full_dispatch_request
    rv = self.handle_user_exception(e)
  File "/Users/justinlabrash/Documents/flask_project/venv/lib/python3.8/site-packages/flask/app.py", line 1821, in handle_user_exception
    reraise(exc_type, exc_value, tb)
  File "/Users/justinlabrash/Documents/flask_project/venv/lib/python3.8/site-packages/flask/_compat.py", line 39, in reraise
    raise value
  File "/Users/justinlabrash/Documents/flask_project/venv/lib/python3.8/site-packages/flask/app.py", line 1948, in full_dispatch_request
    rv = self.preprocess_request()
  File "/Users/justinlabrash/Documents/flask_project/venv/lib/python3.8/site-packages/flask/app.py", line 2242, in preprocess_request
    rv = func()
  File "/Users/justinlabrash/Documents/flask_project/flask_app/main/routes.py", line 18, in before_request
    g.locale = str(get_locale())
NameError: name 'get_locale' is not defined
2020-07-03 11:24:27,389 INFO: Microblog startup [in /Users/justinlabrash/Documents/flask_project/flask_app/__init__.py:75]
2020-07-03 11:24:28,429 ERROR: Exception on / [GET] [in /Users/justinlabrash/Documents/flask_project/venv/lib/python3.8/site-packages/flask/app.py:1891]
Traceback (most recent call last):
  File "/Users/justinlabrash/Documents/flask_project/venv/lib/python3.8/site-packages/flask/app.py", line 2447, in wsgi_app
    response = self.full_dispatch_request()
  File "/Users/justinlabrash/Documents/flask_project/venv/lib/python3.8/site-packages/flask/app.py", line 1952, in full_dispatch_request
    rv = self.handle_user_exception(e)
  File "/Users/justinlabrash/Documents/flask_project/venv/lib/python3.8/site-packages/flask/app.py", line 1821, in handle_user_exception
    reraise(exc_type, exc_value, tb)
  File "/Users/justinlabrash/Documents/flask_project/venv/lib/python3.8/site-packages/flask/_compat.py", line 39, in reraise
    raise value
  File "/Users/justinlabrash/Documents/flask_project/venv/lib/python3.8/site-packages/flask/app.py", line 1950, in full_dispatch_request
    rv = self.dispatch_request()
  File "/Users/justinlabrash/Documents/flask_project/venv/lib/python3.8/site-packages/flask/app.py", line 1936, in dispatch_request
    return self.view_functions[rule.endpoint](**req.view_args)
  File "/Users/justinlabrash/Documents/flask_project/venv/lib/python3.8/site-packages/flask_login/utils.py", line 272, in decorated_view
    return func(*args, **kwargs)
  File "/Users/justinlabrash/Documents/flask_project/flask_app/main/routes.py", line 41, in index
    return render_template('index.html', title=_('Home'), form=form,
NameError: name '_' is not defined
2020-07-03 11:24:49,062 INFO: Microblog startup [in /Users/justinlabrash/Documents/flask_project/flask_app/__init__.py:75]
